<?xml version="1.0"?>
<robot xmlns:xacro="http://www.ros.org/wiki/xacro" >
    <xacro:macro name = "inertial_sphere" params="mass radius *origin">
        <inertial>
            <xacro:insert_block name="origin"/>
            <mass value="${mass}" />
            <inertia ixx="${(2/5)*mass*(radius*radius)}" ixy="0.0" ixz="0.0"
                    iyy="${(2/5)*mass*(radius*radius)}" iyz = "0.0"
                    izz="${(2/5)*mass*(radius*radius)}" />
        </inertial>
    </xacro:macro>

    <xacro:macro name = "inertial_box" params = "mass x y z *origin">
        <inertial>
            <xacro:insert_block name="origin"/>
            <mass value="${mass}"/>
            <inertia ixx="${(1/12)*mass*(y*y+z*z)}" ixy="0.0" ixz="0.0"
                    iyy="${(1/12)*mass*(x*x+z*z)}" iyz = "0.0"
                    izz="${(1/12)*mass*(x*x+y*y)}" />
        </inertial>
    </xacro:macro>

    <xacro:macro name = "inertial_cylinder" params = "mass length radius *origin">
        <inertial>
            <xacro:insert_block name="origin"/>
            <mass value="${mass}"/>
            <inertia ixx="${(1/12)*mass*(3*radius*radius+length*length)}" ixy="0.0" ixz="0.0"
                    iyy="${(1/12)*mass*(3*radius*radius+length*length)}" iyz = "0.0"
                    izz="${(1/2)*mass*(radius*radius)}" />
        </inertial>
    </xacro:macro>

    <!-- wheel macro -->
    <xacro:macro name="wheel_link" params="name parent_link xyz rpy direction">
        <joint name="${name}_joint" type="continuous">
            <parent link="${parent_link}"/>
            <child link="${name}"/>
            <origin xyz="${xyz}" rpy="0 0 0"/>
            <axis xyz="0 1 0"/>
        </joint>

        <link name="${name}">
            <visual>
                <origin xyz="0 0 0" rpy="${rpy}"/>
                <geometry>
                    <cylinder radius="0.03" length="0.03"/>
                </geometry>
                <material name="black"/>
            </visual>
            <collision>
                <origin xyz="0 0 0" rpy="${rpy}"/>
                <geometry>
                    <cylinder radius="0.03" length="0.03"/>
                </geometry>
            </collision>
            
            <xacro:inertial_cylinder mass="0.1" length="0.03" radius="0.03">
                <origin xyz="0 0 0" rpy="0 0 0"/>
            </xacro:inertial_cylinder>
        </link>
    </xacro:macro>
</robot>
                